Workbook
Name C_TBL.C_TBL: #N/A
Name C_TBL.C_TBL: [0]!C_TBL.C_TBL
Name Cancel_DFDS: #REF!
Name CLICK_CTL7: #N/A
Name CLICK_CTL7: [0]!CLICK_CTL7
Name COLNUM: #REF!
Name COLSZ: #REF!
Name Form1_Show: ヘッダ!Form1_Show
Name Form2_Show: ヘッダ!Form2_Show
Name GO: #REF!
Name GOKEI: #REF!
Name IsHoliday: [0]!UF.IsHoliday
Name KAGEN0: #REF!
Name KAGEN1: #REF!
Name Keta: ヘッダ!Keta
Name keta2: ヘッダ!keta2
Name KIJUNZAI: #REF!
Name N_1ｚａｎ: #REF!
Name NEW: #REF!
Name PKNUM: #REF!
Name ｓ: ヘッダ!ｓ
Name sasasaas: ヘッダ!sasasaas
Name sasasas: ヘッダ!sasasas
Name Save_DFEDIT: #REF!
Name レイアウト検討要: #REF!
Name 共通: ヘッダ!共通
Name 共通: [0]!共通
Name 項目一覧NEW: #REF!
Name 種別1: #REF!
Name 帳票種別: #REF!

Sheet 改版履歴
A1: システム | H1: サブシステム | O1: フェーズ | W1: ドキュメント名 | AF1: 機能分類 | AU1: 機能ID | BB1: 画面ID | BL1: 画面名 | CI1: 作成者 | CM1: =$N$8 -> CITS李（佳） | CQ1: 版
CI2: 作成日 | CM2: =$E$8 -> 45918
A3: NICCS | H3: マスタ | O3: 内部設計 | W3: 画面設計書 | AF3: 一般マスタ管理 | AU3: MTI350 | BB3: MTI350S01B02 | BL3: 汎用テーブル詳細（登録） | CI3: 更新者 | CM3: =INDIRECT("N"&(COUNTA($N$7:$N$199)+6)) -> CITS佐藤 | CQ3: =INDIRECT("B"&(COUNTA($B$7:$B$199)+6)) -> 1
CI4: 更新日 | CM4: =INDIRECT("E"&(COUNTA($E$7:$E$199)+6)) -> 46055
B6: ■改版履歴一覧
B7: 版数 | E7: 作成日 | N7: 作成者 | T7: 変更シート | AK7: 変更内容
B8: 0.1 | E8: 45918 | N8: CITS李（佳） | T8: 全体 | AK8: 新規作成
B9: 0.2 | E9: 46001 | N9: CITS李（佳） | T9: 全体 | AK9: 正式版作成
B10: 1 | E10: 46055 | N10: CITS佐藤 | T10: 全体 | AK10: 内部設計書 新規作成

Sheet リスト
A1: 画面項目説明書 | E1: 画面チェック仕様書 | G1: CSVレイアウト
A2: 属性 | B2: 必須 | C2: 表示 | D2: I/O | E2: エラー種別 | F2: WPエラー種別 | G2: 属性
A3: － | B3: ○ | C3: 非表示 | D3: IO入出力 | E3: エラー | F3: IO | G3: CODE
A4: CODE | D4: I入力 | E4: ワーニング | F4: BP | G4: TEXT
A5: TEXT | D5: O出力 | F5: ワーニング | G5: NUM
A6: NUM | D6: Aアクション | G6: DATE
A7: DATE | D7: Gグループ | G7: TIME
A8: TIME | D8: - | G8: BOOL
A9: BOOL | G9: FILE
A10: FILE | G10: -
A11: DM

Sheet 画面定義書
A50: 概要
B52: 汎用マスタ制御マスタの更新、汎用マスタ情報の登録・更新・削除、汎用マスタ（履歴）の登録を行う。
A57: 対象データモデル | U57: 対象条件
A58: 論理名称 | J58: 物理名称
A59: ★汎用マスタ制御マスタ | J59: MTM5210_GNRL_CTRL | V59: 汎用マスタ制御マスタ.汎用データ区分 | AH59: = | AJ59: パラメータ.汎用データ区分
U60: and 汎用マスタ. 汎用区分 = パラメータ.汎用データ区分
A61: 処理対象データモデル
A62: 論理名称 | J62: 物理名称 | S62: CRUD
A63: 汎用マスタ制御マスタ | J63: MTM5210_GNRL_CTRL | S63: RU
A64: ★汎用マスタ
U73: 入出力タイプ | AB73: 外部ファイル | AI73: 部分入出力
U74: IO | AB74: Javascript | AG74: 〇
AB75: CSS | AG75: 〇

Sheet 画面項目説明書
DY1: 欄外
A5: 項番 | B5: 入出力仕様 | AE5: 対象データモデル情報 | AU5: フォーマット | BE5: 初期値 | BS5: 編集仕様 | CC5: 加工式 | CT5: 選択リスト | DD5: 表示条件 | DN5: 備考 | DY5: 項目名
B6: 項目名 | K6: I/O | M6: 必須 | O6: 表示 | Q6: 属性(WP) | T6: 属性 | W6: 桁数(WP) | Z6: 桁数 | AC6: ソート順 | AE6: データモデル名 | AM6: 項目名 | DY6: WP項目名
A7: アクション
A8: =IF(B8<>"",COUNTA($B$8:B8),"") -> 1 | B8: F1 戻る | K8: Aアクション | Q8: － | T8: － | W8: － | Z8: －
A9: ヘッダ
A10: =IF(B10<>"",COUNTA($B$8:B10),"") -> 2 | B10: 汎用データ区分コード | K10: IO入出力 | O10: 非表示 | Q10: DM | T10: CODE | W10: DM | Z10: 5 | AE10: 汎用マスタ制御マスタ | AM10: 汎用データ区分 | BE10: パラメータ.汎用データ区分
A11: =IF(B11<>"",COUNTA($B$8:B11),"") -> 3 | B11: 汎用データ区分 | K11: O出力 | Q11: DM | T11: TEXT | W11: DM | Z11: 255 | AE11: 汎用マスタ制御マスタ | AM11: 汎用データ区分名
A12: =IF(B12<>"",COUNTA($B$8:B12),"") -> 4 | B12: 制御区分 | K12: O出力 | O12: 非表示 | Q12: DM | T12: CODE | W12: DM | Z12: 1 | AE12: 汎用マスタ制御マスタ | AM12: 制御区分
A13: =IF(B13<>"",COUNTA($B$8:B13),"") -> 5 | B13: 汎用CD属性 | K13: O出力 | O13: 非表示 | Q13: DM | T13: CODE | W13: DM | Z13: 1 | AE13: 汎用マスタ制御マスタ | AM13: 汎用CD属性
A14: =IF(B14<>"",COUNTA($B$8:B14),"") -> 6 | B14: 汎用CD属性名 | K14: O出力 | O14: 非表示 | Q14: DM | T14: TEXT | W14: DM | Z14: 100 | AE14: 汎用マスタ | AM14: 汎用名 | CC14: [DM]汎用マスタ [条件]汎用データ区分＝"MT205" [項目]汎用名
A15: =IF(B15<>"",COUNTA($B$8:B15),"") -> 7 | B15: 汎用CD桁数 | K15: O出力 | O15: 非表示 | Q15: DM | T15: NUM | W15: DM | Z15: 3 | AE15: 汎用マスタ制御マスタ | AM15: 汎用CD桁数
A16: =IF(B16<>"",COUNTA($B$8:B16),"") -> 8 | B16: 汎用CD最大値 | K16: O出力 | O16: 非表示 | Q16: DM | T16: NUM | W16: DM | Z16: 10 | AE16: 汎用マスタ制御マスタ | AM16: 汎用CD最大値
A17: =IF(B17<>"",COUNTA($B$8:B17),"") -> 9 | B17: 汎用CD最小値 | K17: O出力 | O17: 非表示 | Q17: DM | T17: NUM | W17: DM | Z17: 10 | AE17: 汎用マスタ制御マスタ | AM17: 汎用CD最小値
A18: =IF(B18<>"",COUNTA($B$8:B18),"") -> 10 | B18: 汎用名属性 | K18: O出力 | O18: 非表示 | Q18: DM | T18: CODE | W18: DM | Z18: 1 | AE18: 汎用マスタ制御マスタ | AM18: 汎用名属性
A19: =IF(B19<>"",COUNTA($B$8:B19),"") -> 11 | B19: 汎用名属性名 | K19: O出力 | O19: 非表示 | Q19: DM | T19: TEXT | W19: DM | Z19: 100 | AE19: 汎用マスタ | AM19: 汎用名 | CC19: [DM]汎用マスタ [条件]汎用データ区分＝"MT206"（汎用名属性名） [項目]汎用名
A20: =IF(B20<>"",COUNTA($B$8:B20),"") -> 12 | B20: 汎用名称桁数 | K20: O出力 | O20: 非表示 | Q20: DM | T20: NUM | W20: DM | Z20: 3 | AE20: 汎用マスタ制御マスタ | AM20: 汎用名称桁数
A21: =IF(B21<>"",COUNTA($B$8:B21),"") -> 13 | B21: 汎用名称カナ桁数 | K21: O出力 | O21: 非表示 | Q21: DM | T21: NUM | W21: DM | Z21: 3 | AE21: 汎用マスタ制御マスタ | AM21: 汎用名称カナ桁数
A22: =IF(B22<>"",COUNTA($B$8:B22),"") -> 14 | B22: 汎用区分1制御FLG | K22: O出力 | O22: 非表示 | Q22: DM | T22: BOOL | W22: DM | Z22: ー | AE22: 汎用マスタ制御マスタ | AM22: 汎用区分1制御FLG
A23: =IF(B23<>"",COUNTA($B$8:B23),"") -> 15 | B23: 汎用数値1制御FLG | K23: O出力 | O23: 非表示 | Q23: DM | T23: BOOL | W23: DM | Z23: ー | AE23: 汎用マスタ制御マスタ | AM23: 汎用数値1制御FLG
A24: =IF(B24<>"",COUNTA($B$8:B24),"") -> 16 | B24: 汎用文字1制御FLG | K24: O出力 | O24: 非表示 | Q24: DM | T24: BOOL | W24: DM | Z24: ー | AE24: 汎用マスタ制御マスタ | AM24: 汎用文字1制御FLG
A25: =IF(B25<>"",COUNTA($B$8:B25),"") -> 17 | B25: 汎用区分2制御FLG | K25: O出力 | O25: 非表示 | Q25: DM | T25: BOOL | W25: DM | Z25: ー | AE25: 汎用マスタ制御マスタ | AM25: 汎用区分2制御FLG
A26: =IF(B26<>"",COUNTA($B$8:B26),"") -> 18 | B26: 汎用数値2制御FLG | K26: O出力 | O26: 非表示 | Q26: DM | T26: BOOL | W26: DM | Z26: ー | AE26: 汎用マスタ制御マスタ | AM26: 汎用数値2制御FLG
A27: =IF(B27<>"",COUNTA($B$8:B27),"") -> 19 | B27: 汎用文字2制御FLG | K27: O出力 | O27: 非表示 | Q27: DM | T27: BOOL | W27: DM | Z27: ー | AE27: 汎用マスタ制御マスタ | AM27: 汎用文字2制御FLG
A28: =IF(B28<>"",COUNTA($B$8:B28),"") -> 20 | B28: 汎用区分3制御FLG | K28: O出力 | O28: 非表示 | Q28: DM | T28: BOOL | W28: DM | Z28: ー | AE28: 汎用マスタ制御マスタ | AM28: 汎用区分3制御FLG
A29: =IF(B29<>"",COUNTA($B$8:B29),"") -> 21 | B29: 汎用数値3制御FLG | K29: O出力 | O29: 非表示 | Q29: DM | T29: BOOL | W29: DM | Z29: ー | AE29: 汎用マスタ制御マスタ | AM29: 汎用数値3制御FLG
A30: =IF(B30<>"",COUNTA($B$8:B30),"") -> 22 | B30: 汎用文字3制御FLG | K30: O出力 | O30: 非表示 | Q30: DM | T30: BOOL | W30: DM | Z30: ー | AE30: 汎用マスタ制御マスタ | AM30: 汎用文字3制御FLG
A31: =IF(B31<>"",COUNTA($B$8:B31),"") -> 23 | B31: 汎用区分4制御FLG | K31: O出力 | O31: 非表示 | Q31: DM | T31: BOOL | W31: DM | Z31: ー | AE31: 汎用マスタ制御マスタ | AM31: 汎用区分4制御FLG
A32: =IF(B32<>"",COUNTA($B$8:B32),"") -> 24 | B32: 汎用数値4制御FLG | K32: O出力 | O32: 非表示 | Q32: DM | T32: BOOL | W32: DM | Z32: ー | AE32: 汎用マスタ制御マスタ | AM32: 汎用数値4制御FLG
A33: =IF(B33<>"",COUNTA($B$8:B33),"") -> 25 | B33: 汎用文字4制御FLG | K33: O出力 | O33: 非表示 | Q33: DM | T33: BOOL | W33: DM | Z33: ー | AE33: 汎用マスタ制御マスタ | AM33: 汎用文字4制御FLG
... A36: =IF(B36<>"",COUNTA($B$8:B36),"") -> 28 | B36: 汎用文字5制御FLG | K36: O出力 | O36: 非表示 | Q36: DM | T36: BOOL | W36: DM | Z36: ー | AE36: 汎用マスタ制御マスタ | AM36: 汎用文字5制御FLG
A37: =IF(B37<>"",COUNTA($B$8:B37),"") -> 29 | B37: 汎用CD見出し | K37: O出力 | O37: 非表示 | Q37: DM | T37: TEXT | W37: DM | Z37: 20 | AE37: 汎用マスタ制御マスタ | AM37: 汎用CD見出し
A38: =IF(B38<>"",COUNTA($B$8:B38),"") -> 30 | B38: 汎用名見出し | K38: O出力 | O38: 非表示 | Q38: DM | T38: TEXT | W38: DM | Z38: 20 | AE38: 汎用マスタ制御マスタ | AM38: 汎用名見出し
A39: =IF(B39<>"",COUNTA($B$8:B39),"") -> 31 | B39: 汎用名カナ見出し | K39: O出力 | O39: 非表示 | Q39: DM | T39: TEXT | W39: DM | Z39: 20 | AE39: 汎用マスタ制御マスタ | AM39: 汎用名カナ見出し
A40: =IF(B40<>"",COUNTA($B$8:B40),"") -> 32 | B40: 汎用区分1見出し | K40: O出力 | O40: 非表示 | Q40: DM | T40: TEXT | W40: DM | Z40: 20 | AE40: 汎用マスタ制御マスタ | AM40: 汎用区分1見出し
A41: =IF(B41<>"",COUNTA($B$8:B41),"") -> 33 | B41: 汎用数値1見出し | K41: O出力 | O41: 非表示 | Q41: DM | T41: TEXT | W41: DM | Z41: 20 | AE41: 汎用マスタ制御マスタ | AM41: 汎用数値1見出し
A42: =IF(B42<>"",COUNTA($B$8:B42),"") -> 34 | B42: 汎用文字1見出し | K42: O出力 | O42: 非表示 | Q42: DM | T42: TEXT | W42: DM | Z42: 20 | AE42: 汎用マスタ制御マスタ | AM42: 汎用文字1見出し
A43: =IF(B43<>"",COUNTA($B$8:B43),"") -> 35 | B43: 汎用区分2見出し | K43: O出力 | O43: 非表示 | Q43: DM | T43: TEXT | W43: DM | Z43: 20 | AE43: 汎用マスタ制御マスタ | AM43: 汎用区分2見出し
A44: =IF(B44<>"",COUNTA($B$8:B44),"") -> 36 | B44: 汎用数値2見出し | K44: O出力 | O44: 非表示 | Q44: DM | T44: TEXT | W44: DM | Z44: 20 | AE44: 汎用マスタ制御マスタ | AM44: 汎用数値2見出し
A45: =IF(B45<>"",COUNTA($B$8:B45),"") -> 37 | B45: 汎用文字2見出し | K45: O出力 | O45: 非表示 | Q45: DM | T45: TEXT | W45: DM | Z45: 20 | AE45: 汎用マスタ制御マスタ | AM45: 汎用文字2見出し
...

Sheet 画面機能定義書
BY1: 欄外
A5: 項番 | B5: 機能名 | N5: 機能説明 | AO5: 項目名 | BA5: 備考 | BY5: 実装メモ
A7: =IF(B7="","",MAX(B7)+1) -> 1 | B7: 初期表示（更新） | N7: 一覧画面より渡されたキー項目に該当するデータを表示する。 | AO7: -
A8: =IF(B8="","",MAX($A$7:$A7)+1) -> 2 | B8: 初期表示（照会） | N8: 一覧画面より渡されたキー項目に該当するデータを表示する。 | AO8: -
A9: =IF(B9="","",MAX($A$7:$A8)+1) -> 3 | B9: 画面遷移（戻る） | N9: 汎用テーブル一覧画面へ画面遷移する。 | AO9: F1 戻る | BA9: アクションボタン
A10: =IF(B10="","",MAX($A$7:$A9)+1) -> 4 | B10: 更新 | N10: 画面表示されている汎用データ区分に該当する汎用マスタ情報を登録、更新、削除し、汎用テーブル一覧へ画面遷移する。 | AO10: F5 更新 | BA10: アクションボタン
A11: =IF(B11="","",MAX($A$7:$A9)+1)
A12: =IF(B12="","",MAX($A$7:$A10)+1)
A13: =IF(B13="","",MAX($A$7:$A12)+1)
A14: =IF(B14="","",MAX($A$7:$A13)+1)
A15: =IF(B15="","",MAX($A$7:$A14)+1)
A16: =IF(B16="","",MAX($A$7:$A15)+1)
A17: =IF(B17="","",MAX($A$7:$A16)+1)
A18: =IF(B18="","",MAX($A$7:$A17)+1)
A19: =IF(B19="","",MAX($A$7:$A18)+1)
A20: =IF(B20="","",MAX($A$7:$A19)+1)
A21: =IF(B21="","",MAX($A$7:$A20)+1)

Sheet 画面チェック仕様書
FV1: 欄外
A5: 項番 | B5: 項目名 | H5: チェック名 | S5: 種別 | W5: チェック仕様 | AY5: チェックアクション | CC5: メッセージID | CH5: メッセージ内容 | DH5: パラメータ | EL5: 備考 | FV5: IO,BP,ワーニング | FW5: 実装メモ | GS5: e-bas 実装有無 | GX5: NICCS 実装要否 | HC5: メモ
AY6: F5 更新 | DH6: {1} | DN6: {2} | DT6: {3} | DZ6: {4} | EF6: {5}
A7: =IF(H8="","",MAX(H7)+1) -> 1 | B7: 汎用データ区分 | H7: (存在チェック)汎用データ区分 | S7: エラー | W7: 汎用データ区分が入力されていて、汎用マスタに存在しない場合エラーとする 以下内容でデータ件数を検索し、０件の場合エラーとする [検索] DM：汎用マスタ 条件：汎用データ区分＝画面.汎用データ区分 | AY7: 〇 | CC7: MZZG0601 | CH7: {1}は存在しません。 | DH7: 汎用データ区分 | GS7: ● | GX7: ●
A8: =IF(H8="","",MAX($A$7:$A7)+1) -> 2 | B8: 汎用コード | H8: (必須チェック)汎用コード | S8: エラー | W8: 汎用コードが未入力の場合エラーとする | AY8: 〇 | CC8: MZZG0101 | CH8: {1}を入力してください。 | DH8: 汎用コード | GS8: ● | GX8: ●
A9: =IF(H9="","",MAX($A$7:$A8)+1) -> 3 | B9: 汎用コード | H9: (桁数チェック)汎用コード | S9: エラー | W9: 画面.汎用CD桁数がNULL以外で、画面.汎用CD桁数≠汎用コードの桁数の場合エラーとする | AY9: 〇 | CC9: MZZG0201 | CH9: {1}は{2}桁で入力してください。 | DH9: 汎用コード | DN9: 画面.汎用CD桁数 | GS9: ● | GX9: ●
A10: =IF(H10="","",MAX($A$9:$A9)+1) -> 4 | B10: 汎用コード | H10: (文字種チェック)汎用コード | S10: エラー | W10: 画面.汎用CD属性がNULL以外で、画面.汎用CD属性≠汎用コードの文字種の場合エラーとする 以下マクロを呼び出し、戻り値がFALSEの場合にエラーとする。 [マクロ] コード：MT_CHK_GNRL1（汎用コード文字種チェック） パラメータ：画面.汎用CD属性、画面.汎用コード | AY10: 〇 | CC10: MZZG0301 | CH10: {1}は{2}で入力してください。 | DH10: 汎用コード | DN10: 画面.汎用CD属性名 | GS10: ● | GX10: ●
A11: =IF(H11="","",MAX($A$9:$A10)+1) -> 5 | B11: 汎用コード | H11: (最大値チェック)汎用コード | S11: エラー | W11: 画面.汎用CD最大値がNULL以外で、画面.汎用CD最大値＜汎用コードの場合エラーとする | AY11: 〇 | CC11: MZZG0402 | CH11: {1}は{2}以下の値で入力してください。 | DH11: 汎用コード | DN11: 画面.汎用コード最大値 | GS11: ● | GX11: ●
A12: =IF(H12="","",MAX($A$11:$A11)+1) -> 6 | B12: 汎用コード | H12: (最小値チェック)汎用コード | S12: エラー | W12: 画面.汎用CD最小値がNULL以外、画面.汎用CD最小値＞汎用コードの場合エラーとする | AY12: 〇 | CC12: MZZG0401 | CH12: {1}は{2}以上の値で入力してください。 | DH12: 汎用コード | DN12: 画面.汎用コード最小値 | GS12: ● | GX12: ●
A13: =IF(H13="","",MAX($A$12:$A12)+1) -> 7 | B13: 汎用コード | H13: (重複チェック)汎用コード | S13: エラー | W13: 一覧内の入力汎用コードが重複している場合エラーとする | AY13: 〇 | CC13: MZZG0605 | CH13: {1}が重複しています。 | DH13: 汎用コード | GS13: ● | GX13: ●
A14: =IF(H14="","",MAX($A$12:$A13)+1) -> 8 | B14: 汎用名 | H14: (必須チェック)汎用名 | S14: エラー | W14: 汎用名が未入力の場合エラーとする | AY14: 〇 | CC14: MZZG0101 | CH14: {1}を入力してください。 | DH14: 汎用名 | GS14: ● | GX14: ●
A15: =IF(H15="","",MAX($A$14:$A14)+1) -> 9 | B15: 汎用名 | H15: (桁数チェック)汎用名 | S15: エラー | W15: 画面.汎用名称桁数がNULL以外で、汎用名称桁数≠汎用名の桁数の場合エラーとする | AY15: 〇 | CC15: MZZG0201 | CH15: {1}は{2}桁で入力してください。 | DH15: 汎用名 | DN15: 画面.汎用名称桁数 | GS15: ● | GX15: ●
A16: =IF(H16="","",MAX($A$15:$A15)+1) -> 10 | B16: 汎用名 | H16: (文字種チェック)汎用名 | S16: エラー | W16: 画面.汎用名属性がNULL以外で、画面.汎用名属性≠汎用名の文字種の場合エラーとする 以下マクロを呼び出し、戻り値がFALSEの場合にエラーとする。 [マクロ] コード：MT_CHK_GNRL2（汎用名文字種チェック） パラメータ：画面.汎用名属性、画面.汎用名 | AY16: 〇 | CC16: MZZG0301 | CH16: {1}は{2}で入力してください。 | DH16: 汎用名 | DN16: 画面.汎用名属性名 | GS16: ● | GX16: ●
A17: =IF(H17="","",MAX($A$15:$A16)+1) -> 11 | B17: 汎用名カナ | H17: (桁数チェック)汎用名カナ | S17: エラー | W17: 画面.汎用名称カナ桁数が設定されて、画面.汎用名称カナ桁数≠汎用名カナの桁数の場合エラーとする | AY17: 〇 | CC17: MZZG0201 | CH17: {1}は{2}桁で入力してください。 | DH17: 汎用名カナ | DN17: 画面.汎用名称カナ桁数 | GS17: ● | GX17: ●
A18: =IF(H18="","",MAX($A$15:$A17)+1) -> 12 | B18: 汎用名 | H18: (文字種チェック)汎用名 | S18: エラー | W18: 画面.汎用名カナがNULL以外で、文字種が全角カナ、全角英数字以外の文字種の場合エラーとする 以下マクロを呼び出し、戻り値がFALSEの場合にエラーとする。 [マクロ] コード：MT_CHK_GNRL3（汎用名カナ文字種チェック） パラメータ：画面.汎用名カナ | AY18: 〇 | CC18: MZZG0301 | CH18: {1}は{2}で入力してください。 | DH18: 汎用名 | DN18: 画面.汎用名属性名 | GS18: ● | GX18: ●
A19: =IF(H19="","",MAX($A$15:$A17)+1) -> 12 | B19: 制御区分 | H19: (追加範囲外チェック)制御区分 | S19: エラー | W19: 画面.制御区分≠"3"（追加変更可）で、追加行が存在する場合エラーとする | AY19: 〇 | CC19: MMTG9999 | CH19: {1}は{2}できません。 | DH19: 行 | DN19: 追加 | GS19: ● | GX19: ●
A20: =IF(H20="","",MAX($A$15:$A19)+1) -> 13 | B20: 制御区分 | H20: (削除範囲外チェック)制御区分 | S20: エラー | W20: 画面.制御区分≠"3"（追加変更可）で、削除行が存在する場合エラーとする | AY20: 〇 | CC20: MMTG9999 | CH20: {1}は{2}できません。 | DH20: 行 | DN20: 削除 | GS20: ● | GX20: ●
A21: =IF(H21="","",MAX($A$15:$A20)+1) -> 14 | B21: 表示順 | H21: (必須チェック)表示順 | S21: エラー | W21: 表示順が未入力の場合エラーとする | AY21: 〇 | CC21: MZZG0101 | CH21: {1}を入力してください。 | DH21: 表示順 | GS21: ● | GX21: ●
A22: BPチェック
A23: =IF(H23="","",MAX($A$15:$A21)+1) -> 15 | B23: ー | H23: 排他チェック | S23: エラー | W23: 画面表示時に取得した汎用マスタ制御マスタの更新数と、ボタン押下時のDBの更新数が異なる場合はエラーとする | AY23: 〇 | CC23: MZZG0801 | CH23: 他ユーザにより更新されています。画面を再度開きなおしてください。 | FV23: BP | GS23: ● | GX23: ●
A24: =IF(H24="","",MAX($A$15:$A23)+1) | GS24: ● | GX24: ●
A25: =IF(H25="","",MAX($A$15:$A24)+1) | GS25: ● | GX25: ●

Sheet 処理機能記述書
BX1: 欄外
BX3: 実装メモ
B6: 1. | C6: パラメータ
C7: 順 | E7: 項目
C8: 1 | E8: 汎用データ区分
B11: 2. | C11: 初期表示処理
C12: なし
B14: 3. | C14: 「更新」ボタン押下処理
C15: 1) | D15: メッセージ
D16: 事前メッセージ | J16: ： | K16: MZZG0003 | Q16: 更新してもよろしいですか？
D17: OKメッセージ | J17: ： | K17: MZZG0004 | Q17: 更新しました。{1} | AA17: {1}：画面.汎用データ区分
D18: NGメッセージ | J18: ： | K18: なし
C20: 2) | D20: 次画面遷移
D21: 変更破棄確認 | J21: ： | K21: なし
D22: 次入出力 | J22: ： | K22: @BACK
E23: パラメータ
E24: 順 | G24: 項目
G25: なし
C27: 3) | D27: 処理内容
D28: (1) 入力チェック
D30: (2) 汎用マスタ制御マスタ更新処理
E31: ①汎用マスタ制御マスタをロックする
F32: ⅰ．データモデル
G33: 汎用マスタ制御マスタ
G34: 操作コード：MTI350S01_L010
F36: ⅱ．対象条件
G37: 汎用データ区分 | M37: ＝ | N37: 画面.汎用データ区分
E39: ②汎用マスタ制御マスタを更新する
F40: ⅰ．データモデル
G41: 汎用マスタ制御マスタ
G42: 操作コード：MTI350S01_U010
F44: ⅱ．対象条件
G45: 汎用データ区分 | M45: ＝ | N45: 画面.汎用データ区分
F47: ⅲ．更新内容
G48: DB設定項目定義_汎用マスタ制御マスタ
D50: (3) 汎用マスタ履歴登録処理
E51: ①汎用マスタを取得する
F52: ⅰ．データモデル
G53: 汎用マスタ
G54: 操作コード：ZZ_R_DATA_KBN
...

Sheet DB設定項目定義_汎用マスタ制御マスタ
A6: データモデル | G6: 汎用マスタ制御マスタ | AF6: 操作 | AL6: 更新
A7: 操作コード | G7: MTI350S01_U010 | AF7: 名前 | AL7: 更新（更新数カウントアップ）
A8: DB設定項目
A9: 項目 | AA9: 設定内容 | AU9: 備考
A10: ユーザ操作用更新日時 | L10: USR_UPDATED_DATE | AA10: @SYSNOW
A11: ユーザ操作用更新ユーザCD | L11: USR_UPDATED_USR_CD | AA11: ＠USER
A12: ユーザ操作用更新機能CD | L12: USR_UPDATED_PRG_CD | AA12: ＠IOCODE
A13: 更新日時 | L13: UPDATED_DATE | AA13: @SYSNOW
A14: 更新ユーザCD | L14: UPDATED_USR_CD | AA14: ＠USER
A15: 更新機能CD | L15: UPDATED_PRG_CD | AA15: ＠IOCODE
A16: 更新数 | L16: MODIFY_COUNT | AA16: 画面.更新数＋１

Sheet DB設定項目定義_汎用マスタ
A6: データモデル | G6: 汎用マスタ | AF6: 操作 | AL6: 登録
A7: 操作コード | G7: MTI350S01_I010 | AF7: 名前 | AL7: 汎用テーブル詳細_登録
A8: DB設定項目
A9: 項目 | AA9: 設定内容 | AU9: 備考
A10: 汎用データ区分 | L10: GENERAL_DATA_KBN | AA10: 画面.汎用データ区分
A11: 汎用CD | L11: GENERAL_CD | AA11: 画面.汎用CD
A12: 汎用名 | L12: GENERAL_NAME | AA12: 画面.汎用名
A13: 汎用名カナ | L13: GENERAL_NAME_KANA | AA13: 画面.汎用名カナ
A14: 表示順 | L14: DISPLAY_ORDER_NO | AA14: 画面.表示順
A15: 汎用区分1 | L15: GENERAL_KBN1 | AA15: 画面.汎用区分1
A16: 汎用区分2 | L16: GENERAL_KBN2 | AA16: 画面.汎用区分2
A17: 汎用区分3 | L17: GENERAL_KBN3 | AA17: 画面.汎用区分3
A18: 汎用区分4 | L18: GENERAL_KBN4 | AA18: 画面.汎用区分4
A19: 汎用区分5 | L19: GENERAL_KBN5 | AA19: 画面.汎用区分5
A20: 汎用文字1 | L20: GENERAL_VARCHAR1 | AA20: 画面.汎用文字1
A21: 汎用文字2 | L21: GENERAL_VARCHAR2 | AA21: 画面.汎用文字2
... A26: 汎用数値2 | L26: GENERAL_NUMERIC2 | AA26: 画面.汎用数値2
A27: 汎用数値3 | L27: GENERAL_NUMERIC3
A28: 汎用数値4 | L28: GENERAL_NUMERIC4
A29: 汎用数値5 | L29: GENERAL_NUMERIC5
A30: ユーザ操作用更新日時 | L30: USR_UPDATED_DATE | AA30: @SYSNOW
A31: ユーザ操作用更新ユーザCD | L31: USR_UPDATED_USR_CD | AA31: ＠USER
A32: ユーザ操作用更新機能CD | L32: USR_UPDATED_PRG_CD | AA32: ＠IOCODE
A33: 作成日時 | L33: CREATED_DATE | AA33: @SYSNOW
A34: 作成ユーザCD | L34: CREATED_USR_CD | AA34: ＠USER
A35: 作成機能CD | L35: CREATED_PRG_CD | AA35: ＠IOCODE
A36: 更新日時 | L36: UPDATED_DATE | AA36: @SYSNOW
A37: 更新ユーザCD | L37: UPDATED_USR_CD | AA37: ＠USER
A38: 更新機能CD | L38: UPDATED_PRG_CD | AA38: ＠IOCODE
A39: 更新数 | L39: MODIFY_COUNT | AA39: 画面.更新数＋１
A40: データモデル | G40: 汎用マスタ | AF40: 操作 | AL40: 更新
A41: 操作コード | G41: MTI350S01_U010 | AF41: 名前 | AL41: 汎用テーブル詳細_更新
A42: DB設定項目
A43: 項目 | AA43: 設定内容 | AU43: 備考
A44: 汎用名 | L44: GENERAL_NAME | AA44: 画面.汎用名
A45: 汎用名カナ | L45: GENERAL_NAME_KANA | AA45: 画面.汎用名カナ
A46: 表示順 | L46: DISPLAY_ORDER_NO | AA46: 画面.表示順
A47: 汎用区分1 | L47: GENERAL_KBN1 | AA47: 画面.汎用区分1
A48: 汎用区分2 | L48: GENERAL_KBN2 | AA48: 画面.汎用区分2
A49: 汎用区分3 | L49: GENERAL_KBN3 | AA49: 画面.汎用区分3
...

Sheet DB設定項目定義_汎用マスタ（履歴）
A6: データモデル | G6: 汎用マスタ（履歴） | AF6: 操作 | AL6: 登録
A7: 操作コード | G7: MTI350S01_I010 | AF7: 名前 | AL7: 汎用テーブル詳細_登録
A8: DB設定項目
A9: 項目 | AA9: 設定内容 | AU9: 備考
A10: プルーフ番号 | L10: PROOF_NO | AA10: （Oracleシーケンスで採番） | AU10: SEQ_MTR5200
A11: プルーフ枝番 | L11: PROOF_BRANCH | AA11: （明細データの件数をカウントアップ）
A12: 履歴データ種別 | L12: HIST_DATA_TYPE | AA12: 固定値：2 | AU12: 2：修正前情報（修正時のみ作成）
A13: 操作種別 | L13: OPERATE_TYPE | AA13: 固定値：@NULL
A14: 汎用データ区分 | L14: GENERAL_DATA_KBN | AA14: 汎用マスタ.汎用データ区分
A15: 汎用データ区分名 | L15: GENERAL_DATA_KBN_NAME | AA15: 汎用マスタ.汎用データ区分名
A16: 汎用CD | L16: GENERAL_CD | AA16: 汎用マスタ.汎用CD
A17: 汎用名 | L17: GENERAL_NAME | AA17: 汎用マスタ.汎用名
A18: 汎用名カナ | L18: GENERAL_NAME_KANA | AA18: 汎用マスタ.汎用名カナ
A19: 表示順 | L19: DISPLAY_ORDER_NO | AA19: 汎用マスタ.表示順
A20: 汎用区分1 | L20: GENERAL_KBN1 | AA20: 汎用マスタ.汎用区分1
A21: 汎用区分2 | L21: GENERAL_KBN2 | AA21: 汎用マスタ.汎用区分2
A22: 汎用区分3 | L22: GENERAL_KBN3 | AA22: 汎用マスタ.汎用区分3
A23: 汎用区分4 | L23: GENERAL_KBN4 | AA23: 汎用マスタ.汎用区分4
A24: 汎用区分5 | L24: GENERAL_KBN5 | AA24: 汎用マスタ.汎用区分5
... A44: 更新数 | L44: MODIFY_COUNT | AA44: 汎用マスタ.更新数

Sheet 補足説明書
A5: 補足説明

Sheet ヘッダ
A1: システム | F1: サブシステム | K1: フェーズ | P1: ドキュメント名 | V1: シート名 | AB1: 機能分類 | AH1: 機能ID | AM1: 画面ID | AT1: 画面名 | BQ1: 作成者 | BU1: =改版履歴!$CM$1 -> CITS李（佳） | BY1: 版
BQ2: 作成日 | BU2: =改版履歴!$CM$2 -> 45918
A3: =改版履歴!$A$3 -> NICCS | F3: =改版履歴!$H$3 -> マスタ | K3: =改版履歴!$O$3 -> 内部設計 | P3: =改版履歴!$W$3 -> 画面設計書 | V3: 凡例 | AB3: =改版履歴!$AF$3 -> 一般マスタ管理 | AH3: =改版履歴!$AU$3 -> MTI350 | AM3: =改版履歴!$BB$3 -> MTI350S01B02 | AT3: =改版履歴!$BL$3 -> 汎用テーブル詳細（登録） | BQ3: 更新者 | BU3: =改版履歴!$CM$3 -> CITS佐藤 | BY3: =改版履歴!$CQ$3 -> 1
BQ4: 更新日 | BU4: =改版履歴!$CM$4 -> 46055
A6: システム | F6: サブシステム | K6: フェーズ | P6: ドキュメント名 | V6: シート名 | AB6: 機能分類 | AH6: 機能ID | AM6: 画面ID | AT6: 画面名 | BQ6: 作成者 | BU6: =改版履歴!$CM$1 -> CITS李（佳） | BY6: 版
BQ7: 作成日 | BU7: =改版履歴!$CM$2 -> 45918
A8: =改版履歴!$A$3 -> NICCS | F8: =改版履歴!$H$3 -> マスタ | K8: =改版履歴!$O$3 -> 内部設計 | P8: =改版履歴!$W$3 -> 画面設計書 | V8: 画面定義書 | AB8: =改版履歴!$AF$3 -> 一般マスタ管理 | AH8: =改版履歴!$AU$3 -> MTI350 | AM8: =改版履歴!$BB$3 -> MTI350S01B02 | AT8: =改版履歴!$BL$3 -> 汎用テーブル詳細（登録） | BQ8: 更新者 | BU8: =改版履歴!$CM$3 -> CITS佐藤 | BY8: =改版履歴!$CQ$3 -> 1
BQ9: 更新日 | BU9: =改版履歴!$CM$4 -> 46055
A11: システム | F11: サブシステム | K11: フェーズ | P11: ドキュメント名 | V11: シート名 | AB11: 機能分類 | AH11: 機能ID | AM11: 画面ID | AT11: 画面名 | BQ11: 作成者 | BU11: =改版履歴!$CM$1 -> CITS李（佳） | BY11: 版
BQ12: 作成日 | BU12: =改版履歴!$CM$2 -> 45918
A13: =改版履歴!$A$3 -> NICCS | F13: =改版履歴!$H$3 -> マスタ | K13: =改版履歴!$O$3 -> 内部設計 | P13: =改版履歴!$W$3 -> 画面設計書 | V13: 画面項目説明書 | AB13: =改版履歴!$AF$3 -> 一般マスタ管理 | AH13: =改版履歴!$AU$3 -> MTI350 | AM13: =改版履歴!$BB$3 -> MTI350S01B02 | AT13: =改版履歴!$BL$3 -> 汎用テーブル詳細（登録） | BQ13: 更新者 | BU13: =改版履歴!$CM$3 -> CITS佐藤 | BY13: =改版履歴!$CQ$3 -> 1
BQ14: 更新日 | BU14: =改版履歴!$CM$4 -> 46055
A16: システム | F16: サブシステム | K16: フェーズ | P16: ドキュメント名 | V16: シート名 | AB16: 機能分類 | AH16: 機能ID | AM16: 画面ID | AT16: 画面名 | BQ16: 作成者 | BU16: =改版履歴!$CM$1 -> CITS李（佳） | BY16: 版
BQ17: 作成日 | BU17: =改版履歴!$CM$2 -> 45918
A18: =改版履歴!$A$3 -> NICCS | F18: =改版履歴!$H$3 -> マスタ | K18: =改版履歴!$O$3 -> 内部設計 | P18: =改版履歴!$W$3 -> 画面設計書 | V18: 画面機能定義書 | AB18: =改版履歴!$AF$3 -> 一般マスタ管理 | AH18: =改版履歴!$AU$3 -> MTI350 | AM18: =改版履歴!$BB$3 -> MTI350S01B02 | AT18: =改版履歴!$BL$3 -> 汎用テーブル詳細（登録） | BQ18: 更新者 | BU18: =改版履歴!$CM$3 -> CITS佐藤 | BY18: =改版履歴!$CQ$3 -> 1
BQ19: 更新日 | BU19: =改版履歴!$CM$4 -> 46055
A21: システム | F21: サブシステム | K21: フェーズ | P21: ドキュメント名 | V21: シート名 | AB21: 機能分類 | AH21: 機能ID | AM21: 画面ID | AT21: 画面名 | BQ21: 作成者 | BU21: =改版履歴!$CM$1 -> CITS李（佳） | BY21: 版
BQ22: 作成日 | BU22: =改版履歴!$CM$2 -> 45918
A23: =改版履歴!$A$3 -> NICCS | F23: =改版履歴!$H$3 -> マスタ | K23: =改版履歴!$O$3 -> 内部設計 | P23: =改版履歴!$W$3 -> 画面設計書 | V23: 画面チェック仕様書 | AB23: =改版履歴!$AF$3 -> 一般マスタ管理 | AH23: =改版履歴!$AU$3 -> MTI350 | AM23: =改版履歴!$BB$3 -> MTI350S01B02 | AT23: =改版履歴!$BL$3 -> 汎用テーブル詳細（登録） | BQ23: 更新者 | BU23: =改版履歴!$CM$3 -> CITS佐藤 | BY23: =改版履歴!$CQ$3 -> 1
BQ24: 更新日 | BU24: =改版履歴!$CM$4 -> 46055
A26: システム | F26: サブシステム | K26: フェーズ | P26: ドキュメント名 | V26: シート名 | AB26: 機能分類 | AH26: 機能ID | AM26: 画面ID | AT26: 画面名 | BQ26: 作成者 | BU26: =改版履歴!$CM$1 -> CITS李（佳） | BY26: 版
BQ27: 作成日 | BU27: =改版履歴!$CM$2 -> 45918
A28: =改版履歴!$A$3 -> NICCS | F28: =改版履歴!$H$3 -> マスタ | K28: =改版履歴!$O$3 -> 内部設計 | P28: =改版履歴!$W$3 -> 画面設計書 | V28: CSVレイアウト | AB28: =改版履歴!$AF$3 -> 一般マスタ管理 | AH28: =改版履歴!$AU$3 -> MTI350 | AM28: =改版履歴!$BB$3 -> MTI350S01B02 | AT28: =改版履歴!$BL$3 -> 汎用テーブル詳細（登録） | BQ28: 更新者 | BU28: =改版履歴!$CM$3 -> CITS佐藤 | BY28: =改版履歴!$CQ$3 -> 1
BQ29: 更新日 | BU29: =改版履歴!$CM$4 -> 46055
A31: システム | F31: サブシステム | K31: フェーズ | P31: ドキュメント名 | V31: シート名 | AB31: 機能分類 | AH31: 機能ID | AM31: 画面ID | AT31: 画面名 | BQ31: 作成者 | BU31: =改版履歴!$CM$1 -> CITS李（佳） | BY31: 版
BQ32: 作成日 | BU32: =改版履歴!$CM$2 -> 45918
A33: =改版履歴!$A$3 -> NICCS | F33: =改版履歴!$H$3 -> マスタ | K33: =改版履歴!$O$3 -> 内部設計 | P33: =改版履歴!$W$3 -> 画面設計書 | V33: 処理機能記述書 | AB33: =改版履歴!$AF$3 -> 一般マスタ管理 | AH33: =改版履歴!$AU$3 -> MTI350 | AM33: =改版履歴!$BB$3 -> MTI350S01B02 | AT33: =改版履歴!$BL$3 -> 汎用テーブル詳細（登録） | BQ33: 更新者 | BU33: =改版履歴!$CM$3 -> CITS佐藤 | BY33: =改版履歴!$CQ$3 -> 1
BQ34: 更新日 | BU34: =改版履歴!$CM$4 -> 46055
A36: システム | F36: サブシステム | K36: フェーズ | P36: ドキュメント名 | V36: シート名 | AB36: 機能分類 | AH36: 機能ID | AM36: 画面ID | AT36: 画面名 | BQ36: 作成者 | BU36: =改版履歴!$CM$1 -> CITS李（佳） | BY36: 版
BQ37: 作成日 | BU37: =改版履歴!$CM$2 -> 45918
A38: =改版履歴!$A$3 -> NICCS | F38: =改版履歴!$H$3 -> マスタ | K38: =改版履歴!$O$3 -> 内部設計 | P38: =改版履歴!$W$3 -> 画面設計書 | V38: DB設定項目定義 | AB38: =改版履歴!$AF$3 -> 一般マスタ管理 | AH38: =改版履歴!$AU$3 -> MTI350 | AM38: =改版履歴!$BB$3 -> MTI350S01B02 | AT38: =改版履歴!$BL$3 -> 汎用テーブル詳細（登録） | BQ38: 更新者 | BU38: =改版履歴!$CM$3 -> CITS佐藤 | BY38: =改版履歴!$CQ$3 -> 1
BQ39: 更新日 | BU39: =改版履歴!$CM$4 -> 46055
A41: システム | F41: サブシステム | K41: フェーズ | P41: ドキュメント名 | V41: シート名 | AB41: 機能分類 | AH41: 機能ID | AM41: 画面ID | AT41: 画面名 | BQ41: 作成者 | BU41: =改版履歴!$CM$1 -> CITS李（佳） | BY41: 版
BQ42: 作成日 | BU42: =改版履歴!$CM$2 -> 45918
A43: =改版履歴!$A$3 -> NICCS | F43: =改版履歴!$H$3 -> マスタ | K43: =改版履歴!$O$3 -> 内部設計 | P43: =改版履歴!$W$3 -> 画面設計書 | V43: 補足説明書 | AB43: =改版履歴!$AF$3 -> 一般マスタ管理 | AH43: =改版履歴!$AU$3 -> MTI350 | AM43: =改版履歴!$BB$3 -> MTI350S01B02 | AT43: =改版履歴!$BL$3 -> 汎用テーブル詳細（登録） | BQ43: 更新者 | BU43: =改版履歴!$CM$3 -> CITS佐藤 | BY43: =改版履歴!$CQ$3 -> 1
BQ44: 更新日 | BU44: =改版履歴!$CM$4 -> 46055
